Workbook

Sheet Previsão Financeira
A2: PREVISÃO FINANCEIRA SEMANAL
B3: SEGUNDA | C3: TERÇA | D3: QUARTA | E3: QUINTA | F3: SEXTA
B4: 46293 | C4: 46294 | D4: 46295 | E4: 46296 | F4: 46297
A6: SALDO INICIAL | B6: 50000
A8: CONTAS À RECEBER
A9: BANRISUL COBRANCA | B9: 52789.7 | C9: 92480.79 | D9: 93660.7 | E9: 89104.97 | F9: 80640.07
A10: BRADESCO COBRANCA | B10: 216519.53 | C10: 191447.63 | D10: 241060.2 | E10: 224287.16 | F10: 182089.12
A11: CARTORIO | B11: 0 | C11: 0 | D11: 0 | E11: 0 | F11: 0
A12: CONTAS A RECEBER | B12: 0 | C12: 73 | D12: 491.1 | E12: 1204.87 | F12: 0
A13: CONTAS À PAGAR | B13: =B23 -> 195926.6 | C13: =B27 -> 141628.96 | D13: =B33 -> 57487.24 | E13: =B38 -> 92943.66 | F13: =B43 -> 69471.61
B14: 0 | C14: 0 | D14: 0 | E14: 0 | F14: 0
A15: SALDO | B15: =B6+B18-B13 | C15: =B15+C18-C13 | D15: =C15+D18-D13 | E15: =D15+E18-E13 | F15: =E15+F18-F13
A16: FUNCIONARIOS | B16: 0 | C16: 0 | D16: 0 | E16: 0 | F16: 0
A17: PROTESTO | B17: 0 | C17: 0 | D17: 0 | E17: 0 | F17: 0
A18: Total | B18: =SUM(B9:B17) | C18: =SUM(C9:C17) | D18: =SUM(D9:D17) | E18: =SUM(E9:E17) | F18: =SUM(F9:F17)
A19: =B4 -> 46293
A20: CONTAS A PAGAR (2) | B20: 192995.62
A21: HONORARIOS ADVOC A PAGAR (99) | B21: 401.34
A22: SEGUROS A PAGAR (51) | B22: 2529.64
A23: Total | B23: =SUM(B20:B22) -> 195926.6
A25: =C4 -> 46294
A26: CONTAS A PAGAR (2) | B26: 141628.96
A27: Total | B27: =SUM(B26:B26) -> 141628.96
A29: =D4 -> 46295
A30: CONTAS A PAGAR (2) | B30: 52834.35
A31: ISS RETIDO A RECOLHER (22) | B31: 118.27
A32: PARCEL FEDERAL 102024 (89) | B32: 4534.62
A33: Total | B33: =SUM(B30:B32) -> 57487.24
A35: =E4 -> 46296
A36: CONTAS A PAGAR (2) | B36: 91093.66
A37: INDENIZACOES TRABALHISTAS (49) | B37: 1850
A38: Total | B38: =SUM(B36:B37) -> 92943.66
A40: =F4 -> 46297
A41: CONTAS A PAGAR (2) | B41: 64951.29
A42: FGTS A RECOLHER (13) | B42: 4520.32
A43: Total | B43: =SUM(B41:B42) -> 69471.61

Sheet Planilha1
A2: PREVISÃO FINANCEIRA SEMANAL
B3: 28/09 - Segunda-Feira | C3: 29/09 - Terça-Feira | D3: 30/09 - Quarta-Feira | E3: 01/10 - Quinta-Feira | F3: 02/10 - Sexta-Feira
B4: 46293 | C4: 46294 | D4: 46295 | E4: 46296 | F4: 46297
A6: SALDO INICIAL | B6: 50000
A8: CONTAS À RECEBER | B8: =SUMIF(Detalhamento!$G:$G,B$4,Detalhamento!$F:$F) -> 17311.84 | C8: =SUMIF(Detalhamento!$G:$G,C$4,Detalhamento!$F:$F) -> 32227.29 | D8: =SUMIF(Detalhamento!$G:$G,D$4,Detalhamento!$F:$F) -> 300774.65 | E8: =SUMIF(Detalhamento!$G:$G,E$4,Detalhamento!$F:$F) -> 298480.96 | F8: =SUMIF(Detalhamento!$G:$G,F$4,Detalhamento!$F:$F) -> 290473.81
A9: Cobrança Bradesc | B9: =SUMIFS(Detalhamento!$F:$F,Detalhamento!$G:$G,B$4,Detalhamento!$B:$B,"BRADESCO COBRANCA") -> 16639.84 | C9: =SUMIFS(Detalhamento!$F:$F,Detalhamento!$G:$G,C$4,Detalhamento!$B:$B,"BRADESCO COBRANCA") -> 24829.04 | D9: =SUMIFS(Detalhamento!$F:$F,Detalhamento!$G:$G,D$4,Detalhamento!$B:$B,"BRADESCO COBRANCA") -> 225371.25 | E9: =SUMIFS(Detalhamento!$F:$F,Detalhamento!$G:$G,E$4,Detalhamento!$B:$B,"BRADESCO COBRANCA") -> 209762.49 | F9: =SUMIFS(Detalhamento!$F:$F,Detalhamento!$G:$G,F$4,Detalhamento!$B:$B,"BRADESCO COBRANCA") -> 174593.03
A10: Cobrança Banrisul | B10: =SUMIFS(Detalhamento!$F:$F,Detalhamento!$G:$G,B$4,Detalhamento!$B:$B,"BANRISUL COBRANCA") -> 672 | C10: =SUMIFS(Detalhamento!$F:$F,Detalhamento!$G:$G,C$4,Detalhamento!$B:$B,"BANRISUL COBRANCA") -> 7325.25 | D10: =SUMIFS(Detalhamento!$F:$F,Detalhamento!$G:$G,D$4,Detalhamento!$B:$B,"BANRISUL COBRANCA") -> 68312.3 | E10: =SUMIFS(Detalhamento!$F:$F,Detalhamento!$G:$G,E$4,Detalhamento!$B:$B,"BANRISUL COBRANCA") -> 77350.2 | F10: =SUMIFS(Detalhamento!$F:$F,Detalhamento!$G:$G,F$4,Detalhamento!$B:$B,"BANRISUL COBRANCA") -> 77668.78
A11: Depósito Clientes | B11: =SUMIFS(Detalhamento!$F:$F,Detalhamento!$G:$G,B$4,Detalhamento!$B:$B,"DEPOSITO (CLIENTE)") -> 0 | C11: =SUMIFS(Detalhamento!$F:$F,Detalhamento!$G:$G,C$4,Detalhamento!$B:$B,"DEPOSITO (CLIENTE)") -> 0 | D11: =SUMIFS(Detalhamento!$F:$F,Detalhamento!$G:$G,D$4,Detalhamento!$B:$B,"DEPOSITO (CLIENTE)") -> 6600 | E11: =SUMIFS(Detalhamento!$F:$F,Detalhamento!$G:$G,E$4,Detalhamento!$B:$B,"DEPOSITO (CLIENTE)") -> 10241.4 | F11: =SUMIFS(Detalhamento!$F:$F,Detalhamento!$G:$G,F$4,Detalhamento!$B:$B,"DEPOSITO (CLIENTE)") -> 38212
A12: Outras carteiras | B12: =B8-B9-B10-B11 -> 0 | C12: =C8-C9-C10-C11 -> 73 | D12: =D8-D9-D10-D11 -> 491.1 | E12: =E8-E9-E10-E11 -> 1126.87 | F12: =F8-F9-F10-F11 -> 0
A13: CONTAS À PAGAR | B13: =SUMIFS(Detalhamento!$H:$H,Detalhamento!$A:$A,B$4,Detalhamento!$D:$D,"*FORNECED*")+SUMIFS(Detalhamento!$H:$H,Detalhamento!$A:$A,B$4,Detalhamento!$D:$D,"*IMPOSTOS*") -> 46172.5 | C13: =SUMIFS(Detalhamento!$H:$H,Detalhamento!$A:$A,C$4,Detalhamento!$D:$D,"*FORNECED*")+SUMIFS(Detalhamento!$H:$H,Detalhamento!$A:$A,C$4,Detalhamento!$D:$D,"*IMPOSTOS*") -> 149305.93 | D13: =SUMIFS(Detalhamento!$H:$H,Detalhamento!$A:$A,D$4,Detalhamento!$D:$D,"*FORNECED*")+SUMIFS(Detalhamento!$H:$H,Detalhamento!$A:$A,D$4,Detalhamento!$D:$D,"*IMPOSTOS*") -> 62395.3 | E13: =SUMIFS(Detalhamento!$H:$H,Detalhamento!$A:$A,E$4,Detalhamento!$D:$D,"*FORNECED*")+SUMIFS(Detalhamento!$H:$H,Detalhamento!$A:$A,E$4,Detalhamento!$D:$D,"*IMPOSTOS*") -> 92943.66 | F13: =SUMIFS(Detalhamento!$H:$H,Detalhamento!$A:$A,F$4,Detalhamento!$D:$D,"*FORNECED*")+SUMIFS(Detalhamento!$H:$H,Detalhamento!$A:$A,F$4,Detalhamento!$D:$D,"*IMPOSTOS*") -> 77091.29
A15: SALDO | B15: =B6+B8-B13 -> 21139.34 | C15: =B15+C8-C13 -> -95939.3 | D15: =C15+D8-D13 -> 142440.05 | E15: =D15+E8-E13 -> 347977.35 | F15: =E15+F8-F13 -> 561359.87
A17: CONTAS À PAGAR
A19: =B3 -> 28/09 - Segunda-Feira
A20: PRF4SISTEMAS | B20: ADVOCACIA GERAL DA UNIAO | C20: 401.34
A21: 221608 | B21: CEREALISTA SERIEMA LTDA | C21: 25894.05
A22: 786 | B22: KOSTER & MATSCHINSKE LTDA - ME | C22: 11826
A23: 221599 | B23: RODRIGO CRISTIANO MICHALSKI IRGANG | C23: 7928.62
A24: 2172049 | B24: TECON RIO GRANDE S/A | C24: 122.49
A25: Total | C25: =SUM(C20:C24) -> 46172.5
A27: =C3 -> 29/09 - Terça-Feira
A28: 19600044 FT | B28: EXPRESSO SAO MIGUEL S/A | C28: 55824.94
A29: 2499391 FT | B29: FL BRASIL HOLDING LOGISTICA E TRANSPORTE | C29: 17315.46
A30: 16 | B30: GILSON SAMPAIO RIBEIRO REPRESENTACOES | C30: 66.73
A31: 95565 | B31: GLOBALFOOD SISTEMAS INGREDIENTES | C31: 11174
A32: 142188 | B32: INDUSTRIA DE BENEFICIAMENTO DE LEITE MAR | C32: 16000
A33: 737 | B33: JSANTOS EMPILHADEIRA DE CARGAS EIRELI ME | C33: 3375
A34: 28092026 | B34: LEANDRO RENATO BERTOLDO | C34: 866.22
A35: 12979 | B35: RODOVIARIO CORSO LTDA | C35: 12217.6
A36: 140602 | B36: SIM REDE DE POSTOS LTDA | C36: 275.66
A37: 3159 FT | B37: TRANSPORTES IRMAOS BOHRER LTDA | C37: 12217.16
A38: 272434 FT | B38: TURBO TRANSPORTES E LOGISTICA LTDA | C38: 12084.38
A39: 32354 | B39: UNIROL ROLAMENTOS RETENT. PECAS LTDA. | C39: 138
... A42: 28092026 | B42: WESLEN MACHADO | C42: 744.02
A43: Total | C43: =SUM(C28:C42) -> 149305.93
A45: =D3 -> 30/09 - Quarta-Feira
A46: 1037793 | B46: (sem nome) | C46: 400
A47: 1182491280 | B47: (sem nome) | C47: 764.1
A48: 1183692167 | B48: (sem nome) | C48: 363.6
A49: 1183697278 | B49: (sem nome) | C49: 361.91
A50: 16142 | B50: (sem nome) | C50: 466.29
...

Sheet Config_Carteiras
A1: Carteira | B1: D+ | C1: Observação | E1: Edite o D+ aqui (ou as datas em Dias_Sem_Compensacao): Detalhamento e Planilha1 recalculam sozinhos. Carteira sem cadastro = D+1.
A2: 100 | B2: 1
A3: 33 | B3: 1
A4: 102 | B4: 0
A5: 74 | B5: 1

Sheet Dias_Sem_Compensacao
A1: Data | B1: Descrição

Sheet Detalhamento
A1: Data bruto | B1: Carteira | C1: Código | D1: Tipo | E1: D+ | F1: Cliente | G1: Entrada banco | H1: Fornecedor/A pagar | I1: Saída banco | J1: Fornecedor | K1: Duplicata
A2: 46287 | B2: BANRISUL COBRANCA | C2: 100 | D2: CLIENTES | E2: =IF(LEFT(D2,6)="CLIENT",IFERROR(VLOOKUP(C2,Config_Carteiras!$A:$B,2,FALSE),1),"") -> 1 | F2: 385 | G2: =IF(LEFT(D2,6)="CLIENT",IF(E2=0,WORKDAY(A2-1,1,Dias_Sem_Compensacao!$A$2:$A$500),WORKDAY(A2,E2,Dias_Sem_Compensacao!$A$2:$A$500)),"") -> 46288 | H2: 0 | I2: 46287 | J2: ADRIANA BEDINOTO GUERRA 01204028079 | K2: 220758
A3: 46287 | B3: BANRISUL COBRANCA | C3: 100 | D3: CLIENTES | E3: =IF(LEFT(D3,6)="CLIENT",IFERROR(VLOOKUP(C3,Config_Carteiras!$A:$B,2,FALSE),1),"") -> 1 | F3: 442.29 | G3: =IF(LEFT(D3,6)="CLIENT",IF(E3=0,WORKDAY(A3-1,1,Dias_Sem_Compensacao!$A$2:$A$500),WORKDAY(A3,E3,Dias_Sem_Compensacao!$A$2:$A$500)),"") -> 46288 | H3: 0 | I3: 46287 | J3: FABIO P LIXINSKI | K3: 221083
A4: 46287 | B4: BANRISUL COBRANCA | C4: 100 | D4: CLIENTES | E4: =IF(LEFT(D4,6)="CLIENT",IFERROR(VLOOKUP(C4,Config_Carteiras!$A:$B,2,FALSE),1),"") -> 1 | F4: 355.6 | G4: =IF(LEFT(D4,6)="CLIENT",IF(E4=0,WORKDAY(A4-1,1,Dias_Sem_Compensacao!$A$2:$A$500),WORKDAY(A4,E4,Dias_Sem_Compensacao!$A$2:$A$500)),"") -> 46288 | H4: 0 | I4: 46287 | J4: PABLO MARQUES DA FONTOURA CORREA 03101692083 | K4: 220504
A5: 46288 | B5: BANRISUL COBRANCA | C5: 100 | D5: CLIENTES | E5: =IF(LEFT(D5,6)="CLIENT",IFERROR(VLOOKUP(C5,Config_Carteiras!$A:$B,2,FALSE),1),"") -> 1 | F5: 1102 | G5: =IF(LEFT(D5,6)="CLIENT",IF(E5=0,WORKDAY(A5-1,1,Dias_Sem_Compensacao!$A$2:$A$500),WORKDAY(A5,E5,Dias_Sem_Compensacao!$A$2:$A$500)),"") -> 46289 | H5: 0 | I5: 46288 | J5: FABIO IRINEU NATIVIDADE PEREIRA | K5: 219988
A6: 46288 | B6: BANRISUL COBRANCA | C6: 100 | D6: CLIENTES | E6: =IF(LEFT(D6,6)="CLIENT",IFERROR(VLOOKUP(C6,Config_Carteiras!$A:$B,2,FALSE),1),"") -> 1 | F6: 1102 | G6: =IF(LEFT(D6,6)="CLIENT",IF(E6=0,WORKDAY(A6-1,1,Dias_Sem_Compensacao!$A$2:$A$500),WORKDAY(A6,E6,Dias_Sem_Compensacao!$A$2:$A$500)),"") -> 46289 | H6: 0 | I6: 46288 | K6: 220560
A7: 46288 | B7: BANRISUL COBRANCA | C7: 100 | D7: CLIENTES | E7: =IF(LEFT(D7,6)="CLIENT",IFERROR(VLOOKUP(C7,Config_Carteiras!$A:$B,2,FALSE),1),"") -> 1 | F7: 656 | G7: =IF(LEFT(D7,6)="CLIENT",IF(E7=0,WORKDAY(A7-1,1,Dias_Sem_Compensacao!$A$2:$A$500),WORKDAY(A7,E7,Dias_Sem_Compensacao!$A$2:$A$500)),"") -> 46289 | H7: 0 | I7: 46288 | J7: SUPERMERCADO TODO DIA LTDA | K7: 220353
A8: 46288 | B8: BANRISUL COBRANCA | C8: 100 | D8: CLIENTES | E8: =IF(LEFT(D8,6)="CLIENT",IFERROR(VLOOKUP(C8,Config_Carteiras!$A:$B,2,FALSE),1),"") -> 1 | F8: 420 | G8: =IF(LEFT(D8,6)="CLIENT",IF(E8=0,WORKDAY(A8-1,1,Dias_Sem_Compensacao!$A$2:$A$500),WORKDAY(A8,E8,Dias_Sem_Compensacao!$A$2:$A$500)),"") -> 46289 | H8: 0 | I8: 46288 | J8: THIARLA DA SILVA SILVEIRA | K8: 220608
A9: 46288 | B9: BANRISUL COBRANCA | C9: 100 | D9: CLIENTES | E9: =IF(LEFT(D9,6)="CLIENT",IFERROR(VLOOKUP(C9,Config_Carteiras!$A:$B,2,FALSE),1),"") -> 1 | F9: 364.96 | G9: =IF(LEFT(D9,6)="CLIENT",IF(E9=0,WORKDAY(A9-1,1,Dias_Sem_Compensacao!$A$2:$A$500),WORKDAY(A9,E9,Dias_Sem_Compensacao!$A$2:$A$500)),"") -> 46289 | H9: 0 | I9: 46288 | K9: 221170
A10: 46289 | B10: BANRISUL COBRANCA | C10: 100 | D10: CLIENTES | E10: =IF(LEFT(D10,6)="CLIENT",IFERROR(VLOOKUP(C10,Config_Carteiras!$A:$B,2,FALSE),1),"") -> 1 | F10: 671.5 | G10: =IF(LEFT(D10,6)="CLIENT",IF(E10=0,WORKDAY(A10-1,1,Dias_Sem_Compensacao!$A$2:$A$500),WORKDAY(A10,E10,Dias_Sem_Compensacao!$A$2:$A$500)),"") -> 46290 | H10: 0 | I10: 46289 | J10: COMERCIO DE ALIMENTOS SANTI LTDA | K10: 219683
A11: 46289 | B11: BANRISUL COBRANCA | C11: 100 | D11: CLIENTES | E11: =IF(LEFT(D11,6)="CLIENT",IFERROR(VLOOKUP(C11,Config_Carteiras!$A:$B,2,FALSE),1),"") -> 1 | F11: 660 | G11: =IF(LEFT(D11,6)="CLIENT",IF(E11=0,WORKDAY(A11-1,1,Dias_Sem_Compensacao!$A$2:$A$500),WORKDAY(A11,E11,Dias_Sem_Compensacao!$A$2:$A$500)),"") -> 46290 | H11: 0 | I11: 46289 | J11: ELZA CELANIRA ESTEVES DE MEDEIROS | K11: 220860
A12: 46290 | B12: BANRISUL COBRANCA | C12: 100 | D12: CLIENTES | E12: =IF(LEFT(D12,6)="CLIENT",IFERROR(VLOOKUP(C12,Config_Carteiras!$A:$B,2,FALSE),1),"") -> 1 | F12: 672 | G12: =IF(LEFT(D12,6)="CLIENT",IF(E12=0,WORKDAY(A12-1,1,Dias_Sem_Compensacao!$A$2:$A$500),WORKDAY(A12,E12,Dias_Sem_Compensacao!$A$2:$A$500)),"") -> 46293 | H12: 0 | I12: 46290 | J12: COMERCIO DE ALIMENTOS SANTI LTDA | K12: 220654
A13: 46293 | B13: BANRISUL COBRANCA | C13: 100 | D13: CLIENTES | E13: =IF(LEFT(D13,6)="CLIENT",IFERROR(VLOOKUP(C13,Config_Carteiras!$A:$B,2,FALSE),1),"") -> 1 | F13: 351.4 | G13: =IF(LEFT(D13,6)="CLIENT",IF(E13=0,WORKDAY(A13-1,1,Dias_Sem_Compensacao!$A$2:$A$500),WORKDAY(A13,E13,Dias_Sem_Compensacao!$A$2:$A$500)),"") -> 46294 | H13: 0 | I13: 46293 | J13: ANTONIO KRAHL TERRA | K13: 221270
A14: 46293 | B14: BANRISUL COBRANCA | C14: 100 | D14: CLIENTES | E14: =IF(LEFT(D14,6)="CLIENT",IFERROR(VLOOKUP(C14,Config_Carteiras!$A:$B,2,FALSE),1),"") -> 1 | F14: 701.25 | G14: =IF(LEFT(D14,6)="CLIENT",IF(E14=0,WORKDAY(A14-1,1,Dias_Sem_Compensacao!$A$2:$A$500),WORKDAY(A14,E14,Dias_Sem_Compensacao!$A$2:$A$500)),"") -> 46294 | H14: 0 | I14: 46293 | J14: COMERCIO E TRANSPORTE DE FRUTAS JUSTO LTDA | K14: 220429
A15: 46293 | B15: BANRISUL COBRANCA | C15: 100 | D15: CLIENTES | E15: =IF(LEFT(D15,6)="CLIENT",IFERROR(VLOOKUP(C15,Config_Carteiras!$A:$B,2,FALSE),1),"") -> 1 | F15: 406 | G15: =IF(LEFT(D15,6)="CLIENT",IF(E15=0,WORKDAY(A15-1,1,Dias_Sem_Compensacao!$A$2:$A$500),WORKDAY(A15,E15,Dias_Sem_Compensacao!$A$2:$A$500)),"") -> 46294 | H15: 0 | I15: 46293 | J15: CRISTIANO DA SILVA DE AVILA | K15: 220947
A16: 46293 | B16: BANRISUL COBRANCA | C16: 100 | D16: CLIENTES | E16: =IF(LEFT(D16,6)="CLIENT",IFERROR(VLOOKUP(C16,Config_Carteiras!$A:$B,2,FALSE),1),"") -> 1 | F16: 586 | G16: =IF(LEFT(D16,6)="CLIENT",IF(E16=0,WORKDAY(A16-1,1,Dias_Sem_Compensacao!$A$2:$A$500),WORKDAY(A16,E16,Dias_Sem_Compensacao!$A$2:$A$500)),"") -> 46294 | H16: 0 | I16: 46293 | J16: DS ATACADO E DISTRIBUICAO DE DOCES E SALGADOS LTDA. | K16: 220430
A17: 46293 | B17: BANRISUL COBRANCA | C17: 100 | D17: CLIENTES | E17: =IF(LEFT(D17,6)="CLIENT",IFERROR(VLOOKUP(C17,Config_Carteiras!$A:$B,2,FALSE),1),"") -> 1 | F17: 1243 | G17: =IF(LEFT(D17,6)="CLIENT",IF(E17=0,WORKDAY(A17-1,1,Dias_Sem_Compensacao!$A$2:$A$500),WORKDAY(A17,E17,Dias_Sem_Compensacao!$A$2:$A$500)),"") -> 46294 | H17: 0 | I17: 46293 | J17: ERICK HUBER CABREIRA | K17: 220958
A18: 46293 | B18: BANRISUL COBRANCA | C18: 100 | D18: CLIENTES | E18: =IF(LEFT(D18,6)="CLIENT",IFERROR(VLOOKUP(C18,Config_Carteiras!$A:$B,2,FALSE),1),"") -> 1 | F18: 3321 | G18: =IF(LEFT(D18,6)="CLIENT",IF(E18=0,WORKDAY(A18-1,1,Dias_Sem_Compensacao!$A$2:$A$500),WORKDAY(A18,E18,Dias_Sem_Compensacao!$A$2:$A$500)),"") -> 46294 | H18: 0 | I18: 46293 | J18: NICARETTA IRMAOS LTDA | K18: 220173
A19: 46293 | B19: BANRISUL COBRANCA | C19: 100 | D19: CLIENTES | E19: =IF(LEFT(D19,6)="CLIENT",IFERROR(VLOOKUP(C19,Config_Carteiras!$A:$B,2,FALSE),1),"") -> 1 | F19: 326 | G19: =IF(LEFT(D19,6)="CLIENT",IF(E19=0,WORKDAY(A19-1,1,Dias_Sem_Compensacao!$A$2:$A$500),WORKDAY(A19,E19,Dias_Sem_Compensacao!$A$2:$A$500)),"") -> 46294 | H19: 0 | I19: 46293 | J19: RESTAURANTE E PADARIA KICOLOSSO LTDA | K19: 220935
A20: 46293 | B20: BANRISUL COBRANCA | C20: 100 | D20: CLIENTES | E20: =IF(LEFT(D20,6)="CLIENT",IFERROR(VLOOKUP(C20,Config_Carteiras!$A:$B,2,FALSE),1),"") -> 1 | F20: 390.6 | G20: =IF(LEFT(D20,6)="CLIENT",IF(E20=0,WORKDAY(A20-1,1,Dias_Sem_Compensacao!$A$2:$A$500),WORKDAY(A20,E20,Dias_Sem_Compensacao!$A$2:$A$500)),"") -> 46294 | H20: 0 | I20: 46293 | J20: RUKART GUILHERME JOST | K20: 221286
A21: 46294 | B21: BANRISUL COBRANCA | C21: 100 | D21: CLIENTES | E21: =IF(LEFT(D21,6)="CLIENT",IFERROR(VLOOKUP(C21,Config_Carteiras!$A:$B,2,FALSE),1),"") -> 1 | F21: 385 | G21: =IF(LEFT(D21,6)="CLIENT",IF(E21=0,WORKDAY(A21-1,1,Dias_Sem_Compensacao!$A$2:$A$500),WORKDAY(A21,E21,Dias_Sem_Compensacao!$A$2:$A$500)),"") -> 46295 | H21: 0 | I21: 46294 | J21: ADRIANA BEDINOTO GUERRA 01204028079 | K21: 220758
... A32: 46294 | B32: BANRISUL COBRANCA | C32: 100 | D32: CLIENTES | E32: =IF(LEFT(D32,6)="CLIENT",IFERROR(VLOOKUP(C32,Config_Carteiras!$A:$B,2,FALSE),1),"") -> 1 | F32: 627.3 | G32: =IF(LEFT(D32,6)="CLIENT",IF(E32=0,WORKDAY(A32-1,1,Dias_Sem_Compensacao!$A$2:$A$500),WORKDAY(A32,E32,Dias_Sem_Compensacao!$A$2:$A$500)),"") -> 46295 | H32: 0 | I32: 46294 | J32: COMERCIO DE ALIMENTOS ROHENKHOL LTDA. | K32: 220679
A33: 46294 | B33: BANRISUL COBRANCA | C33: 100 | D33: CLIENTES | E33: =IF(LEFT(D33,6)="CLIENT",IFERROR(VLOOKUP(C33,Config_Carteiras!$A:$B,2,FALSE),1),"") -> 1 | F33: 1542 | G33: =IF(LEFT(D33,6)="CLIENT",IF(E33=0,WORKDAY(A33-1,1,Dias_Sem_Compensacao!$A$2:$A$500),WORKDAY(A33,E33,Dias_Sem_Compensacao!$A$2:$A$500)),"") -> 46295 | H33: 0 | I33: 46294 | K33: 220684
A34: 46294 | B34: BANRISUL COBRANCA | C34: 100 | D34: CLIENTES | E34: =IF(LEFT(D34,6)="CLIENT",IFERROR(VLOOKUP(C34,Config_Carteiras!$A:$B,2,FALSE),1),"") -> 1 | F34: 1524 | G34: =IF(LEFT(D34,6)="CLIENT",IF(E34=0,WORKDAY(A34-1,1,Dias_Sem_Compensacao!$A$2:$A$500),WORKDAY(A34,E34,Dias_Sem_Compensacao!$A$2:$A$500)),"") -> 46295 | H34: 0 | I34: 46294 | J34: COOPERATIVA AGRÁRIA SAO JOSE LTDA. | K34: 220768
A35: 46294 | B35: BANRISUL COBRANCA | C35: 100 | D35: CLIENTES | E35: =IF(LEFT(D35,6)="CLIENT",IFERROR(VLOOKUP(C35,Config_Carteiras!$A:$B,2,FALSE),1),"") -> 1 | F35: 1523.2 | G35: =IF(LEFT(D35,6)="CLIENT",IF(E35=0,WORKDAY(A35-1,1,Dias_Sem_Compensacao!$A$2:$A$500),WORKDAY(A35,E35,Dias_Sem_Compensacao!$A$2:$A$500)),"") -> 46295 | H35: 0 | I35: 46294 | J35: COOPERATIVA DOS PRODUTORES DE ALECRIM LTDA. | K35: 220687
A36: 46294 | B36: BANRISUL COBRANCA | C36: 100 | D36: CLIENTES | E36: =IF(LEFT(D36,6)="CLIENT",IFERROR(VLOOKUP(C36,Config_Carteiras!$A:$B,2,FALSE),1),"") -> 1 | F36: 577.05 | G36: =IF(LEFT(D36,6)="CLIENT",IF(E36=0,WORKDAY(A36-1,1,Dias_Sem_Compensacao!$A$2:$A$500),WORKDAY(A36,E36,Dias_Sem_Compensacao!$A$2:$A$500)),"") -> 46295 | H36: 0 | I36: 46294 | J36: DESEJOS DO PALADAR LTDA | K36: 221079
A37: 46294 | B37: BANRISUL COBRANCA | C37: 100 | D37: CLIENTES | E37: =IF(LEFT(D37,6)="CLIENT",IFERROR(VLOOKUP(C37,Config_Carteiras!$A:$B,2,FALSE),1),"") -> 1 | F37: 377.7 | G37: =IF(LEFT(D37,6)="CLIENT",IF(E37=0,WORKDAY(A37-1,1,Dias_Sem_Compensacao!$A$2:$A$500),WORKDAY(A37,E37,Dias_Sem_Compensacao!$A$2:$A$500)),"") -> 46295 | H37: 0 | I37: 46294 | J37: DIEGO ANDREI ROHTE | K37: 220480
A38: 46294 | B38: BANRISUL COBRANCA | C38: 100 | D38: CLIENTES | E38: =IF(LEFT(D38,6)="CLIENT",IFERROR(VLOOKUP(C38,Config_Carteiras!$A:$B,2,FALSE),1),"") -> 1 | F38: 1051 | G38: =IF(LEFT(D38,6)="CLIENT",IF(E38=0,WORKDAY(A38-1,1,Dias_Sem_Compensacao!$A$2:$A$500),WORKDAY(A38,E38,Dias_Sem_Compensacao!$A$2:$A$500)),"") -> 46295 | H38: 0 | I38: 46294 | J38: DU-PAO INDUSTRIA E COMERCIO DE PAES LTDA. | K38: 220215
A39: 46294 | B39: BANRISUL COBRANCA | C39: 100 | D39: CLIENTES | E39: =IF(LEFT(D39,6)="CLIENT",IFERROR(VLOOKUP(C39,Config_Carteiras!$A:$B,2,FALSE),1),"") -> 1 | F39: 789.2 | G39: =IF(LEFT(D39,6)="CLIENT",IF(E39=0,WORKDAY(A39-1,1,Dias_Sem_Compensacao!$A$2:$A$500),WORKDAY(A39,E39,Dias_Sem_Compensacao!$A$2:$A$500)),"") -> 46295 | H39: 0 | I39: 46294 | J39: EDER CENAIR PEREIRA | K39: 220692
A40: 46294 | B40: BANRISUL COBRANCA | C40: 100 | D40: CLIENTES | E40: =IF(LEFT(D40,6)="CLIENT",IFERROR(VLOOKUP(C40,Config_Carteiras!$A:$B,2,FALSE),1),"") -> 1 | F40: 366.6 | G40: =IF(LEFT(D40,6)="CLIENT",IF(E40=0,WORKDAY(A40-1,1,Dias_Sem_Compensacao!$A$2:$A$500),WORKDAY(A40,E40,Dias_Sem_Compensacao!$A$2:$A$500)),"") -> 46295 | H40: 0 | I40: 46294 | J40: ELAINE MARIA LENZ | K40: 220695
A41: 46294 | B41: BANRISUL COBRANCA | C41: 100 | D41: CLIENTES | E41: =IF(LEFT(D41,6)="CLIENT",IFERROR(VLOOKUP(C41,Config_Carteiras!$A:$B,2,FALSE),1),"") -> 1 | F41: 1082 | G41: =IF(LEFT(D41,6)="CLIENT",IF(E41=0,WORKDAY(A41-1,1,Dias_Sem_Compensacao!$A$2:$A$500),WORKDAY(A41,E41,Dias_Sem_Compensacao!$A$2:$A$500)),"") -> 46295 | H41: 0 | I41: 46294 | J41: ELIO SEBASTIAO RAUPP | K41: 220211
A42: 46294 | B42: BANRISUL COBRANCA | C42: 100 | D42: CLIENTES | E42: =IF(LEFT(D42,6)="CLIENT",IFERROR(VLOOKUP(C42,Config_Carteiras!$A:$B,2,FALSE),1),"") -> 1 | F42: 656 | G42: =IF(LEFT(D42,6)="CLIENT",IF(E42=0,WORKDAY(A42-1,1,Dias_Sem_Compensacao!$A$2:$A$500),WORKDAY(A42,E42,Dias_Sem_Compensacao!$A$2:$A$500)),"") -> 46295 | H42: 0 | I42: 46294 | J42: ELISANGELA TEREZINHA ANDRADE BATISTA | K42: 220763
A43: 46294 | B43: BANRISUL COBRANCA | C43: 100 | D43: CLIENTES | E43: =IF(LEFT(D43,6)="CLIENT",IFERROR(VLOOKUP(C43,Config_Carteiras!$A:$B,2,FALSE),1),"") -> 1 | F43: 914.7 | G43: =IF(LEFT(D43,6)="CLIENT",IF(E43=0,WORKDAY(A43-1,1,Dias_Sem_Compensacao!$A$2:$A$500),WORKDAY(A43,E43,Dias_Sem_Compensacao!$A$2:$A$500)),"") -> 46295 | H43: 0 | I43: 46294 | J43: ELTON KRONBAUER LTDA | K43: 220483
A44: 46294 | B44: BANRISUL COBRANCA | C44: 100 | D44: CLIENTES | E44: =IF(LEFT(D44,6)="CLIENT",IFERROR(VLOOKUP(C44,Config_Carteiras!$A:$B,2,FALSE),1),"") -> 1 | F44: 484.2 | G44: =IF(LEFT(D44,6)="CLIENT",IF(E44=0,WORKDAY(A44-1,1,Dias_Sem_Compensacao!$A$2:$A$500),WORKDAY(A44,E44,Dias_Sem_Compensacao!$A$2:$A$500)),"") -> 46295 | H44: 0 | I44: 46294 | J44: ENIO LUIZ STANGHERLIN | K44: 220757
A45: 46294 | B45: BANRISUL COBRANCA | C45: 100 | D45: CLIENTES | E45: =IF(LEFT(D45,6)="CLIENT",IFERROR(VLOOKUP(C45,Config_Carteiras!$A:$B,2,FALSE),1),"") -> 1 | F45: 578 | G45: =IF(LEFT(D45,6)="CLIENT",IF(E45=0,WORKDAY(A45-1,1,Dias_Sem_Compensacao!$A$2:$A$500),WORKDAY(A45,E45,Dias_Sem_Compensacao!$A$2:$A$500)),"") -> 46295 | H45: 0 | I45: 46294 | J45: EUCLEIA MARTINELLI 98760181087 | K45: 221045
... A78: 46294 | B78: BANRISUL COBRANCA | C78: 100 | D78: CLIENTES | E78: =IF(LEFT(D78,6)="CLIENT",IFERROR(VLOOKUP(C78,Config_Carteiras!$A:$B,2,FALSE),1),"") -> 1 | F78: 7503 | G78: =IF(LEFT(D78,6)="CLIENT",IF(E78=0,WORKDAY(A78-1,1,Dias_Sem_Compensacao!$A$2:$A$500),WORKDAY(A78,E78,Dias_Sem_Compensacao!$A$2:$A$500)),"") -> 46295 | H78: 0 | I78: 46294 | J78: SILVA ATACAREJO LTDA | K78: 220496
A79: 46294 | B79: BANRISUL COBRANCA | C79: 100 | D79: CLIENTES | E79: =IF(LEFT(D79,6)="CLIENT",IFERROR(VLOOKUP(C79,Config_Carteiras!$A:$B,2,FALSE),1),"") -> 1 | F79: 5306 | G79: =IF(LEFT(D79,6)="CLIENT",IF(E79=0,WORKDAY(A79-1,1,Dias_Sem_Compensacao!$A$2:$A$500),WORKDAY(A79,E79,Dias_Sem_Compensacao!$A$2:$A$500)),"") -> 46295 | H79: 0 | I79: 46294 | K79: 220677
A80: 46294 | B80: BANRISUL COBRANCA | C80: 100 | D80: CLIENTES | E80: =IF(LEFT(D80,6)="CLIENT",IFERROR(VLOOKUP(C80,Config_Carteiras!$A:$B,2,FALSE),1),"") -> 1 | F80: 3224 | G80: =IF(LEFT(D80,6)="CLIENT",IF(E80=0,WORKDAY(A80-1,1,Dias_Sem_Compensacao!$A$2:$A$500),WORKDAY(A80,E80,Dias_Sem_Compensacao!$A$2:$A$500)),"") -> 46295 | H80: 0 | I80: 46294 | K80: 220678
A81: 46294 | B81: BANRISUL COBRANCA | C81: 100 | D81: CLIENTES | E81: =IF(LEFT(D81,6)="CLIENT",IFERROR(VLOOKUP(C81,Config_Carteiras!$A:$B,2,FALSE),1),"") -> 1 | F81: 386 | G81: =IF(LEFT(D81,6)="CLIENT",IF(E81=0,WORKDAY(A81-1,1,Dias_Sem_Compensacao!$A$2:$A$500),WORKDAY(A81,E81,Dias_Sem_Compensacao!$A$2:$A$500)),"") -> 46295 | H81: 0 | I81: 46294 | J81: SILVEIRA BITENCOURT PADARIA E CONFEITARIA LTDA | K81: 220753
A82: 46294 | B82: BANRISUL COBRANCA | C82: 100 | D82: CLIENTES | E82: =IF(LEFT(D82,6)="CLIENT",IFERROR(VLOOKUP(C82,Config_Carteiras!$A:$B,2,FALSE),1),"") -> 1 | F82: 484 | G82: =IF(LEFT(D82,6)="CLIENT",IF(E82=0,WORKDAY(A82-1,1,Dias_Sem_Compensacao!$A$2:$A$500),WORKDAY(A82,E82,Dias_Sem_Compensacao!$A$2:$A$500)),"") -> 46295 | H82: 0 | I82: 46294 | J82: SONIA TEREZINHA SANTOS DOS SANTOS | K82: 221082
...
